Workbook
Name capwealth: finance!$C$9
Name cov_c_1: inputoutput!$C$58
Name cov_c_2: inputoutput!$D$58
Name cov_i_1: inputoutput!$C$59
Name cov_i_2: inputoutput!$D$59
Name cov_m_1: inputoutput!$C$61
Name cov_m_2: inputoutput!$D$61
Name cov_x_1: inputoutput!$C$60
Name cov_x_2: inputoutput!$D$60
Name equityliability_ratio: investments!$C$37
Name glambda_mean: technology!$B$91:$T$91
Name glambda_sd: technology!$B$92:$T$92
Name initialGFCF: investments!$C$7:$U$7
Name investbmatrix: investments!$C$13:$U$31
Name mixed: labour!$C$65
Name normalcaputi: investments!$C$8
Name peradultwealth: finance!$C$2
Name pkweights: investments!$C$35:$U$35
Name skillwealth: finance!$C$6:$E$6
Name vat_rates: government!$C$28:$U$28
Name zmatrix: inputoutput!$C$12:$U$30

Sheet Description
A2: Sheet | B2: Description | C2: unit of measure | D2: Country | E2: Data source
A3: Inputoutput | B3: Zdom includes domestic intermediate trade fd DOM by hh, gov, gfcf | C3: € € | D3: ITA | E3: https://ec.europa.eu/eurostat/web/esa-supply-use-input-tables/data/database
A4: Prices | C4: % | D4: ITA | E4: https://data.oecd.org/price/inflation-cpi.htm
A5: Profits
A6: consumption | B6: COICOP CPA bridge Matrix average equivalised disposable income by income quintile propensity to consume by income quintile distribution of consumption expenditure | C6: % € % % | D6: ITA | E6: https://www.sciencedirect.com/science/article/pii/S2352340920302894 https://www.bancaditalia.it/pubblicazioni/indagine-famiglie/bil-fam2010/en_suppl_06_12n.pdf?language_id=1 -||- own calculations (based on ISTAT and Fidelio data)
A7: investments
A8: internal trade | B8: Zimp and fd imp (hh, gov, gfcf) and Exp | C8: € | D8: ITA | E8: https://ec.europa.eu/eurostat/web/esa-supply-use-input-tables/data/database
A9: hh income
A10: finance | C10: €, % | D10: ITA | E10: https://sdw.ecb.europa.eu/browse.do?node=9691390
A11: labour | B11: LFPR unemployment rate | C11: % % | D11: ITA | E11: https://ec.europa.eu/eurostat/databrowser/view/LFSA_ARGAED__custom_841706/default/table?lang=en https://ec.europa.eu/eurostat/databrowser/view/UNE_EDUC_A__custom_996509/default/table
A12: government | C12: €, % | D12: ITA | E12: https://ec.europa.eu/eurostat/web/government-finance-statistics
E13: https://www.oecd.org/tax/consumption/consumption-tax-trends-italy.pdf
E14: https://www.agenziaentrate.gov.it/portale/web/english/personal-income-tax-rates-and-calculation
E15: https://www.agenziaentrate.gov.it/portale/web/english/corporate-income-tax-ires?inheritRedirect=true
E16: https://www.agenziaentrate.gov.it/portale/documents/20143/314317/CS+27062014+rendite+finanziarie_88_+Com+st+Circolare+tassazione+redditi+finanziari+27+06+14.pdf/28537f70-6fd6-982b-d87d-52c950d3f0b4/-/cs-27062014-rendite-finanziarie
A17: technology | B17: Includes the Leontief and the matrix of tech coeff A mean and sd of percentage changes of A due to technological innovation | C17: - % | D17: ITA | E17: own calculation own calculation based on WIOD 1995-2009

Sheet inputoutput
B2: ind -> | C2: A | D2: B | E2: C | F2: 19 | G2: D | H2: E | I2: F | J2: G | K2: H | L2: I | M2: J | N2: K | O2: L | P2: M-N | Q2: O | R2: P | S2: Q | T2: R | U2: S_T_U
B3: initial output | C3: 5.1486037e+10 | D3: 8.4884507e+09 | E3: 8.4092759e+11 | F3: 55030821130 | G3: 81924583690 | H3: 4.0706804e+10 | I3: 2.5378866e+11 | J3: 3.211711e+11 | K3: 176230440110 | L3: 98492354960 | M3: 129114277810 | N3: 132655074620 | O3: 218428075640 | P3: 257921104010 | Q3: 1.365432e+11 | R3: 7.4505471e+10 | S3: 142940529740 | T3: 41307583470 | U3: 5.6320661e+10
B4: initial value added | C4: 28416700000 | D4: 4597400000 | E4: 226115100000 | F4: 2163900000 | G4: 2.5187698e+10 | H4: 1.2515302e+10 | I4: 81207200000 | J4: 160670200000 | K4: 77901500000 | L4: 51655800000 | M4: 62263900000 | N4: 75909900000 | O4: 188745800000 | P4: 1.359628e+11 | Q4: 103094000000 | R4: 63722900000 | S4: 86051700000 | T4: 16620800000 | U4: 40443900000
B5: initial labour compensation | C5: 2.7103463e+10 | D5: 1.1850157e+09 | E5: 1.5425705e+11 | F5: 1.3547652e+09 | G5: 8.7265658e+09 | H5: 4.3360693e+09 | I5: 6.4778984e+10 | J5: 1.3125536e+11 | K5: 4.5890195e+10 | L5: 3.9139533e+10 | M5: 3.057215e+10 | N5: 4.6340111e+10 | O5: 7.7096556e+09 | P5: 9.5753007e+10 | Q5: 70406000000 | R5: 6.1298652e+10 | S5: 6.91603e+10 | T5: 1.2945292e+10 | U5: 3.4581089e+10
B6: initial capital compensation | C6: 1.3132368e+09 | D6: 3.4123843e+09 | E6: 7.1858047e+10 | F6: 8.0913478e+08 | G6: 1.6461132e+10 | H6: 8.1792325e+09 | I6: 1.6428216e+10 | J6: 2.9414842e+10 | K6: 3.2011305e+10 | L6: 1.2516267e+10 | M6: 3.169175e+10 | N6: 2.9569789e+10 | O6: 1.8103614e+11 | P6: 4.0209793e+10 | Q6: 32688000000 | R6: 2.4242478e+09 | S6: 1.68914e+10 | T6: 3.6755084e+09 | U6: 5.8628107e+09
B8: Initial total output | C8: 3.1179829e+12
B9: initial GDP | C9: 1611279400000
B11: Z Dom | C11: A | D11: B | E11: C | F11: C19 | G11: D | H11: E | I11: F | J11: G | K11: H | L11: I | M11: J | N11: K | O11: L | P11: M+N | Q11: O | R11: P | S11: Q | T11: R | U11: S+T+U | V11: TOT ZOUT
B12: A | C12: 5341434790 | D12: 1864100 | E12: 1.9562474e+10 | F12: 5460790 | G12: 77931400 | H12: 44285300 | I12: 87325760 | J12: 2.6182826e+09 | K12: 328003960 | L12: 1.3462769e+09 | M12: 59023520 | N12: 15287560 | O12: 24434110 | P12: 3.7494528e+08 | Q12: 64730860 | R12: 20334270 | S12: 94505860 | T12: 65568170 | U12: 35171750 | V12: =+SUM(C12:U12) -> 3.0167341e+10
B13: B | C13: 12391470 | D13: 32346200 | E13: 1.9111107e+09 | F13: 7.6170608e+08 | G13: 8.873494e+08 | H13: 1.4420602e+08 | I13: 765840780 | J13: 4.5676869e+08 | K13: 58299380 | L13: 45560540 | M13: 56186280 | N13: 20486600 | O13: 45863180 | P13: 149714930 | Q13: 20211710 | R13: 13919600 | S13: 53049250 | T13: 16896290 | U13: 17072000 | V13: =+SUM(C13:U13) -> 5468979080
B14: C | C14: 8.0011583e+09 | D14: 9.4774401e+08 | E14: 2.0393269e+11 | F14: 2.9372297e+09 | G14: 1633233870 | H14: 3821435040 | I14: 3.8659735e+10 | J14: 2.0694813e+10 | K14: 1.1473123e+10 | L14: 17838805040 | M14: 9.0277764e+09 | N14: 2.5866547e+09 | O14: 3195248190 | P14: 19186526370 | Q14: 1.4705197e+09 | R14: 7.9532354e+08 | S14: 7444451620 | T14: 2385813870 | U14: 2512191650 | V14: =+SUM(C14:U14) -> 3.5854448e+11
B15: C19 | C15: 1.5187533e+09 | D15: 186874490 | E15: 7.7184457e+09 | F15: 4.650432e+09 | G15: 2547061700 | H15: 1.0442709e+09 | I15: 2066994620 | J15: 1278688550 | K15: 5.8213894e+09 | L15: 64638760 | M15: 40288560 | N15: 46344900 | O15: 8187310 | P15: 502647760 | Q15: 349523080 | R15: 6073200 | S15: 107268680 | T15: 24266840 | U15: 70834980 | V15: =+SUM(C15:U15) -> 28052984760
B16: D | C16: 972515590 | D16: 206329910 | E16: 1.7434474e+10 | F16: 1.1015346e+09 | G16: 24870658020 | H16: 1156593580 | I16: 949557940 | J16: 3613853760 | K16: 2071047970 | L16: 1893779700 | M16: 558911390 | N16: 5.6775902e+08 | O16: 165521410 | P16: 1668542150 | Q16: 2.0829286e+09 | R16: 458163410 | S16: 1254963420 | T16: 271145350 | U16: 1338519840 | V16: =+SUM(C16:U16) -> 62636799250
B17: E | C17: 420593980 | D17: 2.5513162e+08 | E17: 1.0037448e+10 | F17: 218641250 | G17: 1731930460 | H17: 8762157210 | I17: 1.0302335e+09 | J17: 830429050 | K17: 7.6629722e+08 | L17: 351360490 | M17: 412392620 | N17: 213376920 | O17: 146384420 | P17: 660075660 | Q17: 436718720 | R17: 112899630 | S17: 619289550 | T17: 198405510 | U17: 1.0843928e+09 | V17: =+SUM(C17:U17) -> 28288158840
B18: F | C18: 5.9737385e+08 | D18: 57362680 | E18: 5789631870 | F18: 370130310 | G18: 539320160 | H18: 4.6062712e+08 | I18: 7.3825517e+10 | J18: 2492092440 | K18: 2024458140 | L18: 7.6752581e+08 | M18: 1508723800 | N18: 670800860 | O18: 2857454940 | P18: 3012718480 | Q18: 2.4239836e+09 | R18: 461279870 | S18: 1922614760 | T18: 255973760 | U18: 436998340 | V18: =+SUM(C18:U18) -> 1.0047459e+11
B19: G | C19: 1.6471028e+09 | D19: 268799660 | E19: 50030903120 | F19: 3417199470 | G19: 3046358510 | H19: 1.8447242e+09 | I19: 6099821640 | J19: 1.5859142e+10 | K19: 6681241960 | L19: 3335318140 | M19: 4347654050 | N19: 1.7267275e+09 | O19: 749133420 | P19: 10038114870 | Q19: 6.537037e+08 | R19: 273220500 | S19: 2914296070 | T19: 864142920 | U19: 658463070 | V19: =+SUM(C19:U19) -> 114456067990
B20: H | C20: 9.7163825e+08 | D20: 380600510 | E20: 28756249850 | F20: 1964370250 | G20: 4027904990 | H20: 1.0133379e+09 | I20: 4986941680 | J20: 19889403840 | K20: 33954954970 | L20: 1.4108678e+09 | M20: 3670724600 | N20: 1.7101139e+09 | O20: 416537060 | P20: 6148609700 | Q20: 1.980176e+09 | R20: 4.7347759e+08 | S20: 9.7864885e+08 | T20: 673927750 | U20: 640731420 | V20: =+SUM(C20:U20) -> 114049216870
B21: I | C21: 42740630 | D21: 32319490 | E21: 3.5888576e+09 | F21: 80690760 | G21: 6.0430715e+08 | H21: 32304980 | I21: 2689837460 | J21: 2.6592964e+09 | K21: 8.2598537e+08 | L21: 619536740 | M21: 1107520930 | N21: 2.6568385e+08 | O21: 337978020 | P21: 2988213120 | Q21: 419467060 | R21: 2.0368134e+08 | S21: 1606597000 | T21: 4.2609167e+08 | U21: 280716880 | V21: =+SUM(C21:U21) -> 18811826420
B22: J | C22: 78204380 | D22: 122660980 | E22: 9.9897193e+09 | F22: 278665170 | G22: 1667742360 | H22: 1231783710 | I22: 3.4749333e+09 | J22: 8.8682632e+09 | K22: 2301755150 | L22: 1559660870 | M22: 1.3300235e+10 | N22: 5.2771225e+09 | O22: 8.0412531e+08 | P22: 1.4709841e+10 | Q22: 2239601160 | R22: 6.146411e+08 | S22: 1566782220 | T22: 1759201900 | U22: 872227850 | V22: =+SUM(C22:U22) -> 70717166900
B23: K | C23: 695023790 | D23: 93486150 | E23: 1.4908375e+10 | F23: 3.2268718e+08 | G23: 9.3086295e+08 | H23: 6.1814768e+08 | I23: 6.5483077e+09 | J23: 1.5205904e+10 | K23: 2811624360 | L23: 2545630090 | M23: 2778749380 | N23: 2.3439399e+10 | O23: 9720820960 | P23: 6376081950 | Q23: 4.0550055e+09 | R23: 450512150 | S23: 1.6841751e+09 | T23: 9.8741546e+08 | U23: 1000205240 | V23: =+SUM(C23:U23) -> 95172413640
... B30: S+T+U | C30: 2.24842e+08 | D30: 10011990 | E30: 1.2420825e+09 | F30: 39769720 | G30: 2.8887073e+08 | H30: 53398090 | I30: 1.0452796e+09 | J30: 786492240 | K30: 212432260 | L30: 1.9865018e+08 | M30: 445954180 | N30: 72562930 | O30: 90249520 | P30: 6.6590305e+08 | Q30: 106077240 | R30: 41834600 | S30: 1.4333327e+09 | T30: 2.1020689e+08 | U30: 2.6642189e+08 | V30: =+SUM(C30:U30) -> 7434372280
B31: TOT Z IN | C31: =+SUM(C12:C30) -> 21255409030 | D31: =+SUM(D12:D30) -> 3168186630 | E31: =+SUM(E12:E30) -> 4.2538642e+11 | F31: =+SUM(F12:F30) -> 17647207720 | G31: =+SUM(G12:G30) -> 45707507870 | H31: =+SUM(H12:H30) -> 25639863130 | I31: =+SUM(I12:I30) -> 162418044390 | J31: =+SUM(J12:J30) -> 143609839570 | ... V31: =+SUM(V12:V30) -> 1332103796870
B34: fd DOM | C34: HH | D34: GOV | E34: GFCF
B35: A | C35: 15419332340 | D35: 486372190 | E35: 2.7427406e+08
B36: B | C36: 1.8254291e+09 | D36: 5458640 | E36: 281053060
B37: C | C37: 1.1570806e+11 | D37: 1.8717371e+09 | E37: 71721873020
B38: C19 | C38: 14862590840 | D38: 11722420 | E38: 195751980
B39: D | C39: 1.7040212e+10 | D39: 107494490 | E39: 1443484050
B40: E | C40: 10730869290 | D40: 354256570 | E40: 281874400
B41: F | C41: 9593419750 | D41: 1338858650 | E41: 141487539630
B42: G | C42: 163363125270 | D42: 4333960290 | E42: 23006836570
B43: H | C43: 39605789150 | D43: 5954159300 | E43: 2185474460
B44: I | C44: 78720192840 | D44: 814591930 | E44: 101210380
B45: J | C45: 30596673840 | D45: 7.0686091e+08 | E45: 17621057100
B46: K | C46: 3.2062651e+10 | D46: 38200230 | E46: 9.6691272e+08
... B54: TOT | C54: 8.0174402e+11 | D54: 322457437100 | E54: 285963039300
B56: Covid shock
C57: 2020 | D57: 2021
B58: consumption | C58: -0.088 | D58: 0.046
B59: investments | C59: -0.124 | D59: 0.032
...

Sheet prices
A1: Initial inflation rate (2010) | B1: 0.0153
A3: initial markups | B3: A | C3: B | D3: C | E3: C19 | F3: D | G3: E | H3: F | I3: G | J3: H | K3: I | L3: J | M3: K | N3: L | O3: M-N | P3: O | Q3: P | R3: Q | S3: R | T3: S-U
B4: 0.61 | C4: 0.61 | D4: 0.246 | E4: 0.06 | F4: 0.13 | G4: 0.17 | H4: 0.32 | I4: 0.63666667 | J4: 0.7225 | K4: 0.4 | L4: 0.77 | M4: 0.74 | N4: 0.61 | O4: 1.405 | P4: 0 | Q4: 0 | R4: 0 | S4: 0.9 | T4: 0.9

Sheet profits

Sheet consumption
A1: COICOP CPA Bridge Matrix | T1: TIZIANO
B2: CP01 | C2: CP02 | D2: CP03 | E2: CP041-043 | F2: CP044 | G2: CP045 | H2: CP05 | I2: CP06 | J2: CP071-072 | K2: CP073 | L2: CP08 | M2: CP09 | N2: CP10 | O2: CP11 | P2: CP121 | Q2: CP122-127 | U2: CP01 | V2: CP02 | W2: CP03 | X2: CP041-043 | Y2: CP044 | Z2: CP045 | AA2: CP05 | AB2: CP06 | AC2: CP071-072 | AD2: CP073 | AE2: CP08 | AF2: CP09 | AG2: CP10 | AH2: CP11 | AI2: CP121 | AJ2: CP122-127 | AM2: CP01 | AN2: CP02 | AO2: CP03 | AP2: CP041-043 | AQ2: CP044 | AR2: CP045 | AS2: CP05 | AT2: CP06 | AU2: CP071-072 | AV2: CP073 | AW2: CP08 | AX2: CP09 | AY2: CP10 | AZ2: CP11 | BA2: CP121 | BB2: CP122-127
A3: CPA_A | B3: 0.13395896 | C3: 0.12741804 | D3: 0.0062755908 | E3: 0.0048449892 | F3: 0.0035845464 | G3: 0.0029527595 | H3: 0.0089296282 | I3: 0.002187504 | J3: 0.0020037662 | K3: 0.0092034163 | L3: 0.0029161646 | M3: 0.0047056952 | N3: 0.0047602814 | O3: 0.038342344 | P3: 0.0054898607 | Q3: 0.0097986031 | T3: CPA_A | U3: 0.14742025 | V3: 3.7349472e-08 | W3: 2.8119124e-09 | X3: 2.3207904e-09 | Y3: 7.9119151e-10 | Z3: 2.9391443e-08 | AA3: 8.928144e-05 | AB3: 1.0486863e-09 | AC3: 3.687923e-08 | AD3: 1.3183102e-13 | AE3: 2.5564108e-10 | AF3: 8.4601367e-08 | AG3: 4.2439381e-13 | AH3: 4.9739678e-10 | AI3: 0.00062700628 | AJ3: 7.9478464e-05 | AL3: CPA_A | AM3: =U3-B3 -> 0.013461294 | AN3: =V3-C3 -> -0.127418 | AO3: =W3-D3 -> -0.006275588 | AP3: =X3-E3 -> -0.0048449869 | AQ3: =Y3-F3 -> -0.0035845456 | AR3: =Z3-G3 -> -0.0029527301 | AS3: =AA3-H3 -> -0.0088403468 | AT3: =AB3-I3 -> -0.0021875029 | ... BB3: =AJ3-Q3 -> -0.0097191246
A4: CPA_B | B4: 0.0010076134 | C4: 0.0010829669 | D4: 0.0008656743 | E4: 0.0015743854 | F4: 0.00770112 | G4: 0.050599293 | H4: 0.00085374567 | I4: 0.00037577614 | J4: 0.00052857464 | K4: 0.0015569025 | L4: 0.00067388736 | M4: 0.00038135352 | N4: 0.00031599198 | O4: 0.00098844336 | P4: 0.00066155061 | Q4: 0.0030790852 | T4: CPA_B | U4: 0.0060297795 | V4: 0.034097788 | W4: 0.0025671044 | X4: 0.0021187399 | Y4: 0.00072230955 | Z4: 0.20147158 | AA4: 0.001093147 | AB4: 0.00095738658 | AC4: 6.7829102e-08 | AD4: 1.2035367e-07 | AE4: 0.0002333847 | AF4: 0.019132088 | AG4: 3.8744564e-07 | AH4: 0.00045409289 | AI4: 0.0021245047 | AJ4: 0.00013464985 | AL4: CPA_B | AM4: =U4-B4 -> 0.0050221661 | AN4: =V4-C4 -> 0.033014821 | AO4: =W4-D4 -> 0.00170143 | AP4: =X4-E4 -> 0.00054435447 | AQ4: =Y4-F4 -> -0.0069788105 | AR4: =Z4-G4 -> 0.15087229 | AS4: =AA4-H4 -> 0.00023940137 | AT4: =AB4-I4 -> 0.00058161044 | ... BB4: =AJ4-Q4 -> -0.0029444354
A5: CPA_C | B5: 0.44982448 | C5: 0.45879057 | D5: 0.58445644 | E5: 0.10826936 | F5: 0.11459032 | G5: 0.056769894 | H5: 0.33756506 | I5: 0.10794521 | J5: 0.32680147 | K5: 0.10837562 | L5: 0.13024104 | M5: 0.057257795 | N5: 0.036319363 | O5: 0.35338011 | P5: 0.069824275 | Q5: 0.07911021 | T5: CPA_C | U5: 0.77105644 | V5: 0.53899398 | W5: 0.69393777 | X5: 0.0001156987 | Y5: 4.4557612e-07 | Z5: 5.0396275e-07 | AA5: 0.12023019 | AB5: 0.25527478 | AC5: 5.3875813e-06 | AD5: 7.4243408e-11 | AE5: 0.0042472716 | AF5: 5.9460422e-05 | AG5: 2.3900629e-10 | AH5: 2.8011944e-07 | AI5: 0.25150154 | AJ5: 0.017672245 | AL5: CPA_C | AM5: =U5-B5 -> 0.32123196 | AN5: =V5-C5 -> 0.080203404 | AO5: =W5-D5 -> 0.10948133 | AP5: =X5-E5 -> -0.10815366 | AQ5: =Y5-F5 -> -0.11458988 | AR5: =Z5-G5 -> -0.05676939 | AS5: =AA5-H5 -> -0.21733487 | AT5: =AB5-I5 -> 0.14732958 | ... BB5: =AJ5-Q5 -> -0.061437965
A6: CPA_C19 | B6: 0.0085432012 | C6: 0.001851766 | D6: 0.0016701635 | E6: 0.0071371063 | F6: 0.050442402 | G6: 0.057023078 | H6: 0.0079798517 | I6: 0.0015208018 | J6: 0.0032079012 | K6: 0.08373083 | L6: 0.002151116 | M6: 0.00079930494 | N6: 0.00073329413 | O6: 0.0050586105 | P6: 0.00074932939 | Q6: 0.006089009 | T6: CPA_C19 | U6: 0.0043026193 | V6: 0.024330873 | W6: 0.0018317872 | X6: 0.0015118515 | Y6: 0.00051541238 | Z6: 0.33544558 | AA6: 0.00078002778 | AB6: 0.00068315432 | AC6: 0.03633369 | AD6: 8.5879762e-08 | AE6: 0.00016653437 | AF6: 3.7740741e-05 | AG6: 2.7646634e-07 | AH6: 0.00032402326 | AI6: 0.001515965 | AJ6: 9.6080963e-05 | AL6: CPA_C19 | AM6: =U6-B6 -> -0.004240582 | AN6: =V6-C6 -> 0.022479107 | AO6: =W6-D6 -> 0.00016162364 | AP6: =X6-E6 -> -0.0056252548 | AQ6: =Y6-F6 -> -0.049926989 | AR6: =Z6-G6 -> 0.2784225 | AS6: =AA6-H6 -> -0.0071998239 | AT6: =AB6-I6 -> -0.00083764744 | ... BB6: =AJ6-Q6 -> -0.005992928
A7: CPA_D | B7: 0.0090518423 | C7: 0.0077606538 | D7: 0.0074763812 | E7: 0.0058184337 | F7: 0.03313625 | G7: 0.26872118 | H7: 0.013368826 | I7: 0.0060860495 | J7: 0.006690893 | K7: 0.011041889 | L7: 0.0074958991 | M7: 0.0039396416 | N7: 0.016383663 | O7: 0.0098093054 | P7: 0.0052882118 | Q7: 0.015440459 | T7: CPA_D | U7: 0.0046196886 | V7: 0.026123868 | W7: 0.0019667755 | X7: 0.0016232631 | Y7: 0.00055339424 | Z7: 0.46306966 | AA7: 0.00083750972 | AB7: 0.00073349745 | AC7: 5.1966964e-08 | AD7: 9.2208429e-08 | AE7: 0.00017880665 | AF7: 4.0521938e-05 | AG7: 2.9683975e-07 | AH7: 0.00034790124 | AI7: 0.0016276798 | AJ7: 0.00010316138 | AL7: CPA_D | AM7: =U7-B7 -> -0.0044321537 | AN7: =V7-C7 -> 0.018363214 | AO7: =W7-D7 -> -0.0055096057 | AP7: =X7-E7 -> -0.0041951706 | AQ7: =Y7-F7 -> -0.032582855 | AR7: =Z7-G7 -> 0.19434848 | AS7: =AA7-H7 -> -0.012531316 | AT7: =AB7-I7 -> -0.0053525521 | ... BB7: =AJ7-Q7 -> -0.015337297
A8: CPA_E | B8: 0.0097120171 | C8: 0.0048522558 | D8: 0.0059754843 | E8: 0.00707148 | F8: 0.24250048 | G8: 0.039102084 | H8: 0.0071151148 | I8: 0.0029944432 | J8: 0.0043163165 | K8: 0.0052345455 | L8: 0.0036832086 | M8: 0.008340996 | N8: 0.015731264 | O8: 0.0074246682 | P8: 0.025965098 | Q8: 0.0073516136 | T8: CPA_E | U8: 1.0550627e-06 | V8: 5.9662718e-06 | W8: 4.4917993e-07 | X8: 3.7072722e-07 | Y8: 0.58776691 | Z8: 7.6446009e-06 | AA8: 1.9127376e-07 | AB8: 1.6751903e-07 | AC8: 1.93206e-06 | AD8: 2.1058924e-11 | AE8: 4.0836565e-08 | AF8: 1.0951598e-06 | AG8: 6.7793429e-11 | AH8: 7.9455054e-08 | AI8: 3.7173591e-07 | AJ8: 2.3560401e-08 | AL8: CPA_E | AM8: =U8-B8 -> -0.009710962 | AN8: =V8-C8 -> -0.0048462896 | AO8: =W8-D8 -> -0.0059750351 | AP8: =X8-E8 -> -0.0070711093 | AQ8: =Y8-F8 -> 0.34526643 | AR8: =Z8-G8 -> -0.03909444 | AS8: =AA8-H8 -> -0.0071149235 | AT8: =AB8-I8 -> -0.0029942757 | ... BB8: =AJ8-Q8 -> -0.0073515901
A9: CPA_F | B9: 0.0023703155 | C9: 0.0019308609 | D9: 0.0027224983 | E9: 0.013294625 | F9: 0.0077952116 | G9: 0.0048834463 | H9: 0.004551081 | I9: 0.0034229969 | J9: 0.0032334457 | K9: 0.0055967102 | L9: 0.0051269138 | M9: 0.0018015228 | N9: 0.0065794113 | O9: 0.0034541192 | P9: 0.002426323 | Q9: 0.0066078828 | T9: CPA_F | U9: 1.4927275e-06 | V9: 8.4412219e-06 | W9: 6.3551035e-07 | X9: 0.0060783392 | Y9: 1.7881439e-07 | Z9: 1.6625383e-11 | AA9: 0.1575645 | AB9: 2.3700988e-07 | AC9: 1.679172e-11 | AD9: 2.9794662e-11 | AE9: 5.7776535e-08 | AF9: 2.0111061e-05 | AG9: 9.5915742e-11 | AH9: 1.1241488e-07 | AI9: 5.2594073e-07 | AJ9: 3.3333811e-08 | AL9: CPA_F | AM9: =U9-B9 -> -0.0023688228 | AN9: =V9-C9 -> -0.0019224197 | AO9: =W9-D9 -> -0.0027218628 | AP9: =X9-E9 -> -0.0072162853 | AQ9: =Y9-F9 -> -0.0077950328 | AR9: =Z9-G9 -> -0.0048834463 | AS9: =AA9-H9 -> 0.15301342 | AT9: =AB9-I9 -> -0.0034227599 | ... BB9: =AJ9-Q9 -> -0.0066078495
A10: CPA_G | B10: 0.25079264 | C10: 0.26099773 | D10: 0.19875592 | E10: 0.12760153 | F10: 0.20879157 | G10: 0.12613558 | H10: 0.31069824 | I10: 0.17082518 | J10: 0.30135541 | K10: 0.16179139 | L10: 0.19367993 | M10: 0.069707018 | N10: 0.07176364 | O10: 0.12526782 | P10: 0.083892257 | Q10: 0.11681475 | T10: CPA_G | U10: 0.05661897 | V10: 0.3201745 | W10: 0.024104829 | X10: 0.019894736 | Y10: 0.0067824077 | Z10: 6.3059871e-07 | AA10: 0.010264531 | AB10: 0.0089897553 | AC10: 0.95624316 | AD10: 1.1301078e-06 | AE10: 0.0021914568 | AF10: 0.86426056 | AG10: 3.6380722e-06 | AH10: 0.0042638826 | AI10: 0.019948867 | AJ10: 0.0012643473 | AL10: CPA_G | AM10: =U10-B10 -> -0.19417367 | AN10: =V10-C10 -> 0.059176772 | AO10: =W10-D10 -> -0.17465109 | AP10: =X10-E10 -> -0.10770679 | AQ10: =Y10-F10 -> -0.20200916 | AR10: =Z10-G10 -> -0.12613495 | AS10: =AA10-H10 -> -0.30043371 | AT10: =AB10-I10 -> -0.16183542 | ... BB10: =AJ10-Q10 -> -0.1155504
A11: CPA_H | B11: 0.039217877 | C11: 0.039593074 | D11: 0.026065907 | E11: 0.033742084 | F11: 0.049642447 | G11: 0.089770665 | H11: 0.049412594 | I11: 0.0099994872 | J11: 0.032742476 | K11: 0.23058476 | L11: 0.034618201 | M11: 0.013475358 | N11: 0.037212824 | O11: 0.016868636 | P11: 0.030394199 | Q11: 0.056867158 | T11: CPA_H | U11: 0.0056242104 | V11: 0.031804336 | W11: 0.0023944383 | X11: 0.0019762313 | Y11: 0.00067372628 | Z11: 6.2640133e-08 | AA11: 0.0010196209 | AB11: 0.00089299178 | AC11: 0.0058465132 | AD11: 0.99999753 | AE11: 0.27730112 | AF11: 0.064991827 | AG11: 3.6138565e-07 | AH11: 0.18412547 | AI11: 0.0019816084 | AJ11: 0.00012559316 | AL11: CPA_H | AM11: =U11-B11 -> -0.033593667 | AN11: =V11-C11 -> -0.0077887381 | AO11: =W11-D11 -> -0.023671468 | AP11: =X11-E11 -> -0.031765853 | AQ11: =Y11-F11 -> -0.04896872 | AR11: =Z11-G11 -> -0.089770602 | AS11: =AA11-H11 -> -0.048392973 | AT11: =AB11-I11 -> -0.0091064955 | ... BB11: =AJ11-Q11 -> -0.056741565
A12: CPA_I | B12: 0.01954987 | C12: 0.020374754 | D12: 0.021043989 | E12: 0.12110859 | F12: 0.020654872 | G12: 0.10547482 | H12: 0.046890868 | I12: 0.082309792 | J12: 0.095166219 | K12: 0.075225393 | L12: 0.16058436 | M12: 0.070709603 | N12: 0.12755843 | O12: 0.051498195 | P12: 0.19133846 | Q12: 0.1229111 | T12: CPA_I | U12: 1.4134818e-06 | V12: 7.9930953e-06 | W12: 6.0177245e-07 | X12: 0.054282751 | Y12: 1.6932151e-07 | Z12: 1.5742776e-11 | AA12: 2.5625206e-07 | AB12: 2.2442752e-07 | AC12: 1.5900283e-11 | AD12: 2.8212926e-11 | AE12: 5.4709301e-08 | AF12: 1.2398459e-08 | AG12: 9.0823778e-11 | AH12: 0.79475743 | AI12: 4.9801965e-07 | AJ12: 3.156419e-08 | AL12: CPA_I | AM12: =U12-B12 -> -0.019548457 | AN12: =V12-C12 -> -0.020366761 | AO12: =W12-D12 -> -0.021043387 | AP12: =X12-E12 -> -0.066825837 | AQ12: =Y12-F12 -> -0.020654703 | AR12: =Z12-G12 -> -0.10547482 | AS12: =AA12-H12 -> -0.046890612 | AT12: =AB12-I12 -> -0.082309567 | ... BB12: =AJ12-Q12 -> -0.12291107
A13: CPA_J | B13: 0.0096495959 | C13: 0.010614622 | D13: 0.0079965552 | E13: 0.043485761 | F13: 0.057085436 | G13: 0.050831947 | H13: 0.016489637 | I13: 0.010532624 | J13: 0.036540476 | K13: 0.028133044 | L13: 0.1183597 | M13: 0.045513003 | N13: 0.04314436 | O13: 0.017075229 | P13: 0.040042871 | Q13: 0.050309415 | T13: CPA_J | U13: 5.6340823e-06 | V13: 3.1860161e-05 | W13: 2.3986411e-06 | X13: 1.9797001e-06 | Y13: 6.7490884e-07 | Z13: 6.2750082e-11 | AA13: 0.081458975 | AB13: 8.9455921e-07 | AC13: 6.3377897e-11 | AD13: 1.124556e-10 | AE13: 0.71210253 | AF13: 0.0019378518 | AG13: 3.6201998e-10 | AH13: 4.2429358e-07 | AI13: 1.9850866e-06 | AJ13: 0.18128724 | AL13: CPA_J | AM13: =U13-B13 -> -0.0096439618 | AN13: =V13-C13 -> -0.010582762 | AO13: =W13-D13 -> -0.0079941566 | AP13: =X13-E13 -> -0.043483781 | AQ13: =Y13-F13 -> -0.057084762 | AR13: =Z13-G13 -> -0.050831947 | AS13: =AA13-H13 -> 0.064969338 | AT13: =AB13-I13 -> -0.01053173 | ... BB13: =AJ13-Q13 -> 0.13097782
A14: CPA_K | B14: 0.014157974 | C14: 0.0087222462 | D14: 0.016905221 | E14: 0.15512522 | F14: 0.039430871 | G14: 0.012935253 | H14: 0.02297863 | I14: 0.012251716 | J14: 0.024581988 | K14: 0.035598101 | L14: 0.026892816 | M14: 0.018160548 | N14: 0.027000722 | O14: 0.022950419 | P14: 0.025819705 | Q14: 0.067184312 | T14: CPA_K | U14: 1.4096596e-06 | V14: 7.9714814e-06 | W14: 6.0014522e-07 | X14: 4.9532526e-07 | Y14: 1.6886365e-07 | Z14: 1.5700207e-11 | AA14: 2.5555913e-07 | AB14: 2.2382065e-07 | AC14: 1.5857287e-11 | AD14: 2.8136636e-11 | AE14: 5.4561363e-08 | AF14: 1.2364933e-08 | AG14: 9.0578183e-11 | AH14: 1.0615917e-07 | AI14: 4.9667296e-07 | AJ14: 0.47144817 | AL14: CPA_K | AM14: =U14-B14 -> -0.014156565 | AN14: =V14-C14 -> -0.0087142747 | AO14: =W14-D14 -> -0.016904621 | AP14: =X14-E14 -> -0.15512473 | AQ14: =Y14-F14 -> -0.039430702 | AR14: =Z14-G14 -> -0.012935253 | AS14: =AA14-H14 -> -0.022978375 | AT14: =AB14-I14 -> -0.012251493 | ... BB14: =AJ14-Q14 -> 0.40426386
... A21: CPA_S-T | B21: 0.0015748245 | C21: 0.0016606343 | D21: 0.005852892 | E21: 0.014621952 | F21: 0.018375366 | G21: 0.0025659675 | H21: 0.017559198 | I21: 0.22424363 | J21: 0.0031999197 | K21: 0.0030852747 | L21: 0.0085852613 | M21: 0.088672712 | N21: 0.019455583 | O21: 0.018884181 | P21: 0.021055558 | Q21: 0.028258218 | T21: CPA_S-T | U21: 4.0336782e-05 | V21: 0.00022810039 | W21: 0.22190449 | X21: 1.4173512e-05 | Y21: 4.8319583e-06 | Z21: 4.4925442e-10 | AA21: 0.27447612 | AB21: 0.032776218 | AC21: 5.7514995e-08 | AD21: 8.0511731e-10 | AE21: 0.0005083503 | AF21: 2.0759398e-06 | AG21: 2.5918544e-09 | AH21: 3.0376975e-06 | AI21: 0.71916212 | AJ21: 0.037550664 | AL21: CPA_S-T | AM21: =U21-B21 -> -0.0015344877 | AN21: =V21-C21 -> -0.0014325339 | AO21: =W21-D21 -> 0.2160516 | AP21: =X21-E21 -> -0.014607779 | AQ21: =Y21-F21 -> -0.018370534 | AR21: =Z21-G21 -> -0.002565967 | AS21: =AA21-H21 -> 0.25691692 | AT21: =AB21-I21 -> -0.19146741 | ... BB21: =AJ21-Q21 -> 0.0092924466
A22: TOT | B22: =SUM(B3:B21) -> 1 | C22: =SUM(C3:C21) -> 1 | D22: =SUM(D3:D21) -> 1 | E22: =SUM(E3:E21) -> 1 | F22: =SUM(F3:F21) -> 1 | G22: =SUM(G3:G21) -> 1 | H22: =SUM(H3:H21) -> 1 | I22: =SUM(I3:I21) -> 1 | ... Q22: =SUM(Q3:Q21) -> 1 | U22: =SUM(U3:U21) -> 1 | V22: =SUM(V3:V21) -> 1 | W22: =SUM(W3:W21) -> 1 | X22: =SUM(X3:X21) -> 1 | Y22: =SUM(Y3:Y21) -> 1 | Z22: =SUM(Z3:Z21) -> 1 | AA22: =SUM(AA3:AA21) -> 1 | AB22: =SUM(AB3:AB21) -> 1 | ... AJ22: =SUM(AJ3:AJ21) -> 1
A23: quintile | B23: q1 | C23: q2 | D23: q3 | E23: q4 | F23: q5
A24: equivalent income | B24: 8195.6345 | C24: 16905.4 | D24: 20037.54 | E24: 24814.608 | F24: 34110.63 | G24: 103050 | H24: 1000000 | I24: 10000000
A25: propensity to consume | B25: 1.1848 | C25: 0.9195 | D25: 0.8407 | E25: 0.7592 | F25: 0.6545 | G25: 0.4 | H25: 0.2 | I25: 0.1
A27: beta adjusted to Fidelio | B27: 8195.6345 | C27: 16905.4 | D27: 20037.54 | E27: 24814.608 | F27: 34110.63 | G27: 1000000
A28: CP01 | B28: 0.2097 | C28: 0.1887 | D28: 0.16 | E28: 0.1396 | F28: 0.1031 | G28: 0.1
A29: CP02 | B29: 0.049 | C29: 0.039 | D29: 0.0415 | E29: 0.0406 | F29: 0.0361 | G29: 0.015
A30: CP03 | B30: 0.0585 | C30: 0.0624 | D30: 0.0687 | E30: 0.0663 | F30: 0.0684 | G30: 0.06
A31: CP041-043 | B31: 0.1975 | C31: 0.1835 | D31: 0.1699 | E31: 0.1581 | F31: 0.1461 | G31: 0.1
A32: CP044 | B32: 0.0256 | C32: 0.023 | D32: 0.0207 | E32: 0.0192 | F32: 0.0166 | G32: 0.025
A33: CP045 | B33: 0.073 | C33: 0.0579 | D33: 0.0477 | E33: 0.0393 | F33: 0.0271 | G33: 0.03
A34: CP05 | B34: 0.0587 | C34: 0.058 | D34: 0.0595 | E34: 0.0677 | F34: 0.0817 | G34: 0.1
A35: CP06 | B35: 0.0368 | C35: 0.0323 | D35: 0.0309 | E35: 0.0282 | F35: 0.0322 | G35: 0.045
A36: CP071-072 | B36: 0.0664 | C36: 0.0875 | D36: 0.0987 | E36: 0.1048 | F36: 0.1284 | G36: 0.15
A37: CP073 | B37: 0.0142 | C37: 0.0152 | D37: 0.0155 | E37: 0.0165 | F37: 0.0192 | G37: 0.02
A38: CP08 | B38: 0.0381 | C38: 0.0339 | D38: 0.0305 | E38: 0.0268 | F38: 0.0211 | G38: 0.02
... A43: CP122-127 | B43: 0.0521 | C43: 0.0504 | D43: 0.0576 | E43: 0.0544 | F43: 0.0643 | G43: 0.04
B44: 1.0001 | C44: 1 | D44: 1.0001 | E44: 1.0001 | F44: 1.0001 | G44: 1

Sheet investments
B2: ind -> | C2: A | D2: B | E2: C | F2: 19 | G2: D | H2: E | I2: F | J2: G | K2: H | L2: I | M2: J | N2: K | O2: L | P2: M-N | Q2: O | R2: P | S2: Q | T2: R | U2: S_T_U
B3: initial fixed capital | C3: 208070500000 | D3: 24588500000 | E3: 4.242276e+11 | F3: 29643300000 | G3: 1.8349161e+11 | H3: 9.117359e+10 | I3: 75573200000 | J3: 172516700000 | K3: 356701000000 | L3: 103689000000 | M3: 81046100000 | N3: 85265000000 | O3: 2750392300000 | P3: 116785900000 | Q3: 582673600000 | R3: 35430900000 | S3: 87985500000 | T3: 37623100000 | U3: 22505500000
B4: depreciation rates | C4: 0.049321421 | D4: 0.058811343 | E4: 0.098839292 | F4: 0.056907601 | G4: 0.042295792 | H4: 0.042295792 | I4: 0.086772468 | J4: 0.0841634 | K4: 0.047370605 | L4: 0.049420865 | M4: 0.13168628 | N4: 0.06872217 | O4: 0.012879469 | P4: 0.10901151 | Q4: 0.049518519 | R4: 0.054450402 | S4: 0.065501093 | T4: 0.093008387 | U4: 0.085973642
B5: lifetime of fixed capital | C5: 20.275166 | D5: 17.003523 | E5: 10.117434 | F5: 17.572345 | G5: 23.643014 | H5: 23.643014 | I5: 11.524393 | J5: 11.881649 | K5: 21.110138 | L5: 20.234368 | M5: 7.5938054 | N5: 14.551345 | O5: 77.642954 | P5: 9.1733428 | Q5: 20.194465 | R5: 18.365337 | S5: 15.266921 | T5: 10.751719 | U5: 11.631472
B6: initial capital productivity | C6: 0.32992664 | D6: 0.46029648 | E6: 2.6430077 | F6: 2.475244 | G6: 0.59530124 | H6: 0.59530124 | I6: 4.4775785 | J6: 2.4822416 | K6: 0.65874182 | L6: 1.2665104 | M6: 2.1241294 | N6: 2.0743971 | O6: 0.10588943 | P6: 2.9446603 | Q6: 0.31245212 | R6: 2.8037861 | S6: 2.1661221 | T6: 1.4639091 | U6: 3.3367014
B7: initial GFCF desired | C7: 8.0919034e+09 | D7: 2.4972923e+09 | E7: 5.2443324e+10 | F7: 2.6398195e+09 | G7: 1.0665384e+10 | H7: 3.6089859e+09 | I7: 7.7847359e+09 | J7: 1.6930634e+10 | K7: 2.2217242e+10 | L7: 6.3904035e+09 | M7: 1.4312371e+10 | N7: 5.3730157e+09 | O7: 9.6761481e+10 | P7: 2.0556066e+10 | Q7: 2.7439926e+10 | R7: 2.0257632e+09 | S7: 9.3769711e+09 | T7: 3.2651181e+09 | U7: 1.8439342e+09
B8: normal capacity utilization | C8: 0.8
B10: GFCF transformation Matrix (B)
C11: GFCF demand
B12: industries | C12: A | D12: B | E12: C | F12: C19 | G12: D | H12: E | I12: F | J12: G | K12: H | L12: I | M12: J | N12: K | O12: L | P12: M+N | Q12: O | R12: P | S12: Q | T12: R | U12: S+T+U
A13: GFCF supply | B13: A | C13: 0.070251448 | D13: 0 | E13: 0 | F13: 0 | G13: 0 | H13: 0 | I13: 0 | J13: 0 | K13: 0 | L13: 0 | M13: 0 | N13: 0 | O13: 0 | P13: 0 | Q13: 0 | R13: 0 | S13: 0 | T13: 0.024054497 | U13: 0
B14: B | C14: 5.5625621e-06 | D14: 0.00077308394 | E14: 0.0010738316 | F14: 1.1093299e-05 | G14: 1.1282149e-05 | H14: 1.638449e-05 | I14: 5.2692151e-05 | J14: 9.0763224e-05 | K14: 1.4997009e-05 | L14: 4.5656202e-06 | M14: 0.0011941974 | N14: 0.00062854768 | O14: 5.5537571e-07 | P14: 0.0024025375 | Q14: 1.0644751e-05 | R14: 8.2111568e-05 | S14: 0.00067331969 | T14: 0.0013759902 | U14: 4.6378027e-05
B15: C | C15: 0.58906044 | D15: 0.24316448 | E15: 0.64874914 | F15: 0.45772093 | G15: 0.3892912 | H15: 0.63416744 | I15: 0.69987002 | J15: 0.64568994 | K15: 0.52818254 | L15: 0.56774146 | M15: 0.31369175 | N15: 0.19765877 | O15: 0.0089540432 | P15: 0.3693001 | Q15: 0.27458034 | R15: 0.45607115 | S15: 0.33261336 | T15: 0.3906065 | U15: 0.53315115
B16: C19 | C16: 0.0011988211 | D16: 0.00049487404 | E16: 0.0013202961 | F16: 0.00093152669 | G16: 0.00079226254 | H16: 0.0012906203 | I16: 0.0014243343 | J16: 0.0013140702 | K16: 0.001074926 | L16: 0.001155434 | M16: 0.00063840699 | N16: 0.0004022635 | O16: 1.8222742e-05 | P16: 0.00075157783 | Q16: 0.00055880974 | R16: 0.00092816915 | S16: 0.00067691513 | T16: 0.00079493935 | U16: 0.0010850378
B17: D | C17: 2.8131549e-05 | D17: 0.003909718 | E17: 0.0054306892 | F17: 5.6102148e-05 | G17: 5.705722e-05 | H17: 8.2861294e-05 | I17: 0.00026648006 | J17: 0.00045901692 | K17: 7.5844386e-05 | L17: 2.3089715e-05 | M17: 0.0060394154 | N17: 0.0031787547 | O17: 2.808702e-06 | P17: 0.012150355 | Q17: 5.3833709e-05 | R17: 0.0004152629 | S17: 0.0034051802 | T17: 0.0069587961 | U17: 0.00023454763
B18: E | C18: 5.5028228e-06 | D18: 0.00076478139 | E18: 0.0010622991 | F18: 1.0974162e-05 | G18: 1.1160984e-05 | H18: 1.6208528e-05 | I18: 5.2126262e-05 | J18: 8.978847e-05 | K18: 1.4835948e-05 | L18: 4.5165877e-06 | M18: 0.0011813723 | N18: 0.00062179738 | O18: 5.4941124e-07 | P18: 0.0023767354 | Q18: 1.0530432e-05 | R18: 8.1229729e-05 | S18: 0.00066608855 | T18: 0.0013612127 | U18: 4.5879949e-05
B19: F | C19: 0.31327952 | D19: 0.57810515 | E19: 0.10769726 | F19: 0.49169426 | G19: 0.52630723 | H19: 0.30549925 | I19: 0.24432849 | J19: 0.23516603 | K19: 0.40526426 | L19: 0.38887709 | M19: 0.10910073 | N19: 0.45524709 | O19: 0.92155096 | P19: 0.11286905 | Q19: 0.62508143 | R19: 0.38872643 | S19: 0.46798013 | T19: 0.24537208 | U19: 0.37226618
B20: G | C20: 0.00045561442 | D20: 0.063321216 | E20: 0.087954641 | F20: 0.00090862211 | G20: 0.00092409032 | H20: 0.0013420093 | I20: 0.0043158717 | J20: 0.0074341704 | K20: 0.0012283645 | L20: 0.00037395761 | M20: 0.09781348 | N20: 0.051482642 | O20: 4.5489323e-05 | P20: 0.19678535 | Q20: 0.00087188282 | R20: 0.0067255366 | S20: 0.055149796 | T20: 0.11270363 | U20: 0.0037986988
B21: H | C21: 4.4530658e-05 | D21: 0.0061888634 | E21: 0.0085964751 | F21: 8.8806539e-05 | G21: 9.0318366e-05 | H21: 0.00013116476 | I21: 0.00042182292 | J21: 0.00072659793 | K21: 0.00012005739 | L21: 3.6549718e-05 | M21: 0.0095600543 | N21: 0.0050317896 | O21: 4.446017e-06 | P21: 0.019233327 | Q21: 8.5215729e-05 | R21: 0.00065733777 | S21: 0.0053902084 | T21: 0.011015382 | U21: 0.00037127569
B22: I | C22: 1.9768442e-06 | D22: 0.00027474147 | E22: 0.00038162229 | F22: 3.9423781e-06 | G22: 4.0094924e-06 | H22: 5.8227816e-06 | I22: 1.8725934e-05 | J22: 3.2255775e-05 | K22: 5.3296934e-06 | L22: 1.6225473e-06 | M22: 0.00042439835 | N22: 0.00022337563 | O22: 1.973715e-07 | P22: 0.00085382279 | Q22: 3.7829717e-06 | R22: 2.9181117e-05 | S22: 0.00023928688 | T22: 0.00048900455 | U22: 1.6481997e-05
B23: J | C23: 0.0024363335 | D23: 0.013015991 | E23: 0.063539248 | F23: 0.011964847 | G23: 0.043361968 | H23: 0.034116129 | I23: 0.028143956 | J23: 0.086209826 | K23: 0.0334835 | L23: 0.013087941 | M23: 0.37862467 | N23: 0.2134414 | O23: 0.0020589252 | P23: 0.12663625 | Q23: 0.052416934 | R23: 0.11281114 | S23: 0.05742649 | T23: 0.10235174 | U23: 0.058921623
B24: K | C24: 1.9331781e-05 | D24: 0.0026867277 | E24: 0.0037319272 | F24: 3.8552957e-05 | G24: 3.9209276e-05 | H24: 5.6941634e-05 | I24: 0.00018312301 | J24: 0.00031543284 | K24: 5.211967e-05 | L24: 1.5867072e-05 | M24: 0.0041502391 | N24: 0.0021844154 | O24: 1.9301181e-06 | P24: 0.0083496288 | Q24: 3.6994104e-05 | R24: 0.00028536542 | S24: 0.0023400132 | T24: 0.0047820303 | U24: 0.0001611793
B25: L | C25: 0.022888537 | D25: 0.042236981 | E25: 0.0078684768 | F25: 0.035923709 | G25: 0.03845257 | H25: 0.022320102 | I25: 0.017850901 | J25: 0.017181482 | K25: 0.029609041 | L25: 0.028411776 | M25: 0.0079710163 | N25: 0.03326084 | O25: 0.0673295 | P25: 0.0082463338 | Q25: 0.045669119 | R25: 0.028400769 | S25: 0.034191129 | T25: 0.017927147 | U25: 0.027198166
... B31: S+T+U | C31: 1.0110919e-05 | D31: 0.0014052138 | E31: 0.0019518746 | F31: 2.0163989e-05 | G31: 2.0507257e-05 | H31: 2.9781645e-05 | I31: 9.57771e-05 | J31: 0.00016497786 | K31: 2.7259659e-05 | L31: 8.2988046e-06 | M31: 0.0021706603 | N31: 0.0011424941 | O31: 1.0094914e-06 | P31: 0.0043670275 | Q31: 1.9348677e-05 | R31: 0.00014925198 | S31: 0.001223875 | T31: 0.0025011001 | U31: 8.4300087e-05
B33: price of capital weights
C34: A | D34: B | E34: C | F34: C19 | G34: D | H34: E | I34: F | J34: G | K34: H | L34: I | M34: J | N34: K | O34: L | P34: M+N | Q34: O | R34: P | S34: Q | T34: R | U34: S+T+U
C35: 0.0021679095 | D35: 0.00090973211 | E35: 0.30680653 | F35: 0.0006243946 | G35: 0.0046007889 | H35: 0.00089996202 | I35: 0.45030944 | J35: 0.074513699 | K35: 0.0072827897 | L35: 0.00032330401 | M35: 0.062471062 | N35: 0.0031616262 | O35: 0.03290009 | P35: 0.044404163 | Q35: 0.0005865554 | R35: 0.001162195 | S35: 0.0037208126 | T35: 0.0015013476 | U35: 0.0016535955
B37: eqity to liabilities ratio | C37: 0.37914047 | E37: 1- debt total market Book debt to capital ratio, from Damodaram

Sheet internationaltrade
A1: Z imp | B1: A | C1: B | D1: C | E1: C19 | F1: D | G1: E | H1: F | I1: G | J1: H | K1: I | L1: J | M1: K | N1: L | O1: M+N | P1: O | Q1: P | R1: Q | S1: R | T1: S+T+U | V1: HH IMP | W1: GOV IMP | X1: GFCF IMP | AA1: EXP
A2: A | B2: 484278540 | C2: 262830 | D2: 6.8079754e+09 | E2: 925800 | F2: 21215810 | G2: 292190 | H2: 11660980 | I2: 1.2139732e+08 | J2: 21199980 | K2: 411859280 | L2: 14701970 | M2: 1978140 | N2: 3607740 | O2: 3.756391e+08 | P2: 2104590 | Q2: 230820 | R2: 7411110 | S2: 4279110 | T2: 2867710 | V2: 3269358910 | W2: 0 | X2: 406942400 | Z2: A | AA2: 5157357730
A3: B | B3: 11054280 | C3: 205672910 | D3: 4863846940 | E3: 29534178500 | F3: 6084284960 | G3: 183114960 | H3: 66297350 | I3: 2093846520 | J3: 373391730 | K3: 218145130 | L3: 18798990 | M3: 36793050 | N3: 30792770 | O3: 99993190 | P3: 237809140 | Q3: 4421280 | R3: 92452990 | S3: 35820380 | T3: 33913460 | V3: 8714994240 | W3: 0 | X3: 4812880 | Z3: B | AA3: 907541600
A4: C | B4: 608267390 | C4: 293885010 | D4: 152858928820 | E4: 8.5130872e+08 | F4: 1.0311036e+09 | G4: 216507310 | H4: 4.5033564e+09 | I4: 3.5276982e+09 | J4: 2166686140 | K4: 4.882085e+08 | L4: 2.9372707e+09 | M4: 56629250 | N4: 1.2234886e+08 | O4: 2.8502309e+09 | P4: 333976600 | Q4: 15041190 | R4: 4673810350 | S4: 2.3048704e+08 | T4: 254446320 | V4: 6.1241444e+10 | W4: 4.3440786e+09 | X4: 24684213080 | Z4: C | AA4: 2.9313638e+11
A5: C19 | B5: 7633310 | C5: 3330960 | D5: 2.2772304e+09 | E5: 2300971970 | F5: 654050180 | G5: 1057430 | H5: 154945580 | I5: 23774230 | J5: 3.4046541e+09 | K5: 160690 | L5: 5021910 | M5: 101170 | N5: 37820 | O5: 8471400 | P5: 662220 | Q5: 23750 | R5: 466000 | S5: 298160 | T5: 240340 | V5: 1632831760 | W5: 0 | X5: 449740 | Z5: C19 | AA5: 11907771130
A6: D | B6: 648740 | C6: 4194740 | D6: 224241890 | E6: 1614860360 | F6: 2767730100 | G6: 11289180 | H6: 7175130 | I6: 1.2407917e+08 | J6: 36153450 | K6: 13909960 | L6: 11513040 | M6: 19574570 | N6: 1865250 | O6: 22159860 | P6: 212413190 | Q6: 352570 | R6: 6122060 | S6: 2761110 | T6: 2041770 | V6: 477108240 | W6: 0 | X6: 2202670 | Z6: D | AA6: 696613900
A7: E | B7: 598180 | C7: 158810 | D7: 2.3588126e+09 | E7: 1402540 | F7: 32021840 | G7: 283687910 | H7: 11845630 | I7: 13291990 | J7: 130851560 | K7: 5947350 | L7: 4270160 | M7: 330430 | N7: 48720 | O7: 31485680 | P7: 29715840 | Q7: 22030 | R7: 915890 | S7: 383270 | T7: 15219720 | V7: 1047100 | W7: 0 | X7: 917530 | Z7: E | AA7: 1051698320
A8: F | B8: 1351270 | C8: 2605830 | D8: 1.3321659e+08 | E8: 4337720 | F8: 5262850 | G8: 7835070 | H8: 198030780 | I8: 40003480 | J8: 20084000 | K8: 9279150 | L8: 24100400 | M8: 8052230 | N8: 13227430 | O8: 61232780 | P8: 195585280 | Q8: 5457340 | R8: 17463520 | S8: 3700210 | T8: 3829430 | V8: 9574100 | W8: 0 | X8: 10661750 | Z8: F | AA8: 894447690
A9: G | B9: 29159830 | C9: 16197500 | D9: 3331193180 | E9: 204440580 | F9: 106446550 | G9: 42429610 | H9: 237162150 | I9: 1286911190 | J9: 618588940 | K9: 1.0976327e+08 | L9: 4.8139434e+08 | M9: 1.3411349e+08 | N9: 25634250 | O9: 894723480 | P9: 22579280 | Q9: 7237370 | R9: 145048820 | S9: 37241390 | T9: 12409670 | V9: 1642791820 | W9: 104492370 | X9: 407191380 | Z9: G | AA9: 16013528090
A10: H | B10: 43478480 | C10: 16937110 | D10: 1.6212392e+09 | E10: 100588310 | F10: 3.5216035e+08 | G10: 68963770 | H10: 2.937108e+08 | I10: 1.0085609e+09 | J10: 2411719440 | K10: 1.070614e+08 | L10: 3.36257e+08 | M10: 102542620 | N10: 28315690 | O10: 4.9837248e+08 | P10: 423204770 | Q10: 14727480 | R10: 60966950 | S10: 25768580 | T10: 36113250 | V10: 5484086960 | W10: 0 | X10: 102959530 | Z10: H | AA10: 14499135320
A11: I | B11: 3527890 | C11: 4554250 | D11: 6.0183634e+08 | E11: 12049430 | F11: 37502720 | G11: 6747920 | H11: 224414320 | I11: 5.5354712e+08 | J11: 122425630 | K11: 47466990 | L11: 206024230 | M11: 45100480 | N11: 81900310 | O11: 653468630 | P11: 67950 | Q11: 5387220 | R11: 1.0957242e+08 | S11: 41732640 | T11: 10133970 | V11: 28146890 | W11: 0 | X11: 379260 | Z11: I | AA11: 44533390
A12: J | B12: 5681570 | C12: 17534570 | D12: 2.4985178e+09 | E12: 14725550 | F12: 5.2305131e+08 | G12: 70853820 | H12: 980156000 | I12: 8.6555102e+08 | J12: 5.0953839e+08 | K12: 166834270 | L12: 1685827060 | M12: 6.0704055e+08 | N12: 100404540 | O12: 1.8031093e+09 | P12: 60573220 | Q12: 29415830 | R12: 174035170 | S12: 175951700 | T12: 81954720 | V12: 1.6278027e+09 | W12: 0 | X12: 2.0088596e+09 | Z12: J | AA12: 9472519190
A13: K | B13: 1.1360889e+08 | C13: 8634620 | D13: 1.3520325e+09 | E13: 26572430 | F13: 37184990 | G13: 87077660 | H13: 3.7933602e+08 | I13: 1.1002948e+09 | J13: 489749720 | K13: 149157530 | L13: 2.3051637e+08 | M13: 2221520730 | N13: 119756190 | O13: 716544870 | P13: 65911590 | Q13: 23365210 | R13: 1.3836013e+08 | S13: 79548730 | T13: 42984220 | V13: 57958230 | W13: 0 | X13: 26558940 | Z13: K | AA13: 4414897380
... A20: S+T+U | B20: 2525430 | C20: 629140 | D20: 1.9253479e+08 | E20: 3519970 | F20: 17829280 | G20: 2188770 | H20: 58191400 | I20: 46664160 | J20: 17642830 | K20: 5705890 | L20: 61872320 | M20: 6841180 | N20: 7647140 | O20: 63169410 | P20: 2032180 | Q20: 1260380 | R20: 65350580 | S20: 4368980 | T20: 3369900 | V20: 1.0211661e+08 | W20: 0 | X20: 44767150 | Z20: S+T+U | AA20: 3.8086341e+08
A21: TOT Z IMP | B21: =SUM(B2:B20) -> 1370002030 | C21: =SUM(C2:C20) -> 646526060 | D21: =SUM(D2:D20) -> 183485821710 | E21: =SUM(E2:E20) -> 34828287640 | F21: =SUM(F2:F20) -> 11837552100 | G21: =SUM(G2:G20) -> 1329331510 | H21: =SUM(H2:H20) -> 8.321575e+09 | I21: =SUM(I2:I20) -> 13889650660 | ... T21: =SUM(T2:T20) -> 653620900 | V21: =SUM(V2:V20) -> 85569213120 | W21: =SUM(W2:W20) -> 4.532813e+09 | X21: =SUM(X2:X20) -> 28261368830 | AA21: =+SUM(AA2:AA20) -> 3.7585526e+11
B23: A | C23: B | D23: C | E23: C19 | F23: D | G23: E | H23: F | I23: G | J23: H | K23: I | L23: J | M23: K | N23: L | O23: M+N | P23: O | Q23: P | R23: Q | S23: R | T23: S+T+U
A24: EXP | B24: 5138716660 | C24: 907530790 | D24: 2.9308144e+11 | E24: 11907771130 | F24: 696593580 | G24: 1.0516447e+09 | H24: 894252650 | I24: 16011107660 | J24: 14435800330 | K24: 44533390 | L24: 9472519060 | M24: 4414897380 | N24: 1506869280 | O24: 1.4137485e+10 | P24: 99401920 | Q24: 63277570 | R24: 9.331724e+08 | S24: 5.3664665e+08 | T24: 3.8086318e+08 | U24: 375715000000
A26: Final demand shares (elementwise ratio between f_imp and f_tot)
A27: Sector | C27: f_HH_imp/f_HH_tot | D27: f_gov_imp/f_gov_tot | E27: f_gfcf_imp/f_gfcf_tot
A28: 1 | B28: A | C28: 0.17493782 | D28: 0 | E28: 0.59737605
A29: 2 | B29: B | C29: 0.82681634 | D29: 0 | E29: 0.016836144
A30: 3 | B30: C | C30: 0.34609559 | D30: 0.69887506 | E30: 0.25604414
A31: 4 | B31: C19 | C31: 0.098986961 | D31: 0 | E31: 0.0022922327
A32: 5 | B32: D | C32: 0.027236371 | D32: 0 | E32: 0.001523615
A33: 6 | B33: E | C33: 9.7568781e-05 | D33: 0 | E33: 0.003244541
A34: 7 | B34: F | C34: 0.00099699116 | D34: 0 | E34: 7.5349014e-05
A35: 8 | B35: G | C35: 0.009955957 | D35: 0.023542522 | E35: 0.017390915
A36: 9 | B36: H | C36: 0.12162568 | D36: 0 | E36: 0.044991261
A37: 10 | B37: I | C37: 0.00035742836 | D37: 0 | E37: 0.0037332547
A38: 11 | B38: J | C38: 0.05051448 | D38: 0 | E38: 0.10233663
A39: 12 | B39: K | C39: 0.0018043939 | D39: 0 | E39: 0.026733465
... A46: 19 | B46: S+T+U | C46: 0.0021843095 | D46: 0 | E46: 0.099202485
A48: Intermediate trade ratios (elementwise ratio between Z_imp and Z_dom)
A49: Sector | C49: 1 | D49: 2 | E49: 3 | F49: 4 | G49: 5 | H49: 6 | I49: 7 | J49: 8 | K49: 9 | L49: 10 | M49: 11 | N49: 12 | O49: 13 | P49: 14 | Q49: 15 | R49: 16 | S49: 17 | T49: 18 | U49: 19
A50: 1 | B50: A | C50: =B2/inputoutput!C12 -> 0.090664505 | D50: =C2/inputoutput!D12 -> 0.14099565 | E50: =D2/inputoutput!E12 -> 0.34801197 | F50: =E2/inputoutput!F12 -> 0.16953591 | G50: =F2/inputoutput!G12 -> 0.27223699 | H50: =G2/inputoutput!H12 -> 0.0065979004 | I50: =H2/inputoutput!I12 -> 0.13353425 | J50: =I2/inputoutput!J12 -> 0.046365248 | ... U50: =T2/inputoutput!U12 -> 0.08153447
A51: 2 | B51: B | C51: =B3/inputoutput!C13 -> 0.89208786 | D51: =C3/inputoutput!D13 -> 6.3584876 | E51: =D3/inputoutput!E13 -> 2.5450368 | F51: =E3/inputoutput!F13 -> 38.77372 | G51: =F3/inputoutput!G13 -> 6.8566959 | H51: =G3/inputoutput!H13 -> 1.2698149 | I51: =H3/inputoutput!I13 -> 0.086568059 | J51: =I3/inputoutput!J13 -> 4.5840413 | ... U51: =T3/inputoutput!U13 -> 1.986496
A52: 3 | B52: C | C52: =B4/inputoutput!C14 -> 0.076022417 | D52: =C4/inputoutput!D14 -> 0.31008902 | E52: =D4/inputoutput!E14 -> 0.74955578 | F52: =E4/inputoutput!F14 -> 0.28983389 | G52: =F4/inputoutput!G14 -> 0.63132638 | H52: =G4/inputoutput!H14 -> 0.056656023 | I52: =H4/inputoutput!I14 -> 0.116487 | J52: =I4/inputoutput!J14 -> 0.17046292 | ... U52: =T4/inputoutput!U14 -> 0.1012846
A53: 4 | B53: C19 | C53: =B5/inputoutput!C15 -> 0.0050260367 | D53: =C5/inputoutput!D15 -> 0.017824584 | E53: =D5/inputoutput!E15 -> 0.29503743 | F53: =E5/inputoutput!F15 -> 0.49478672 | G53: =F5/inputoutput!G15 -> 0.25678615 | H53: =G5/inputoutput!H15 -> 0.0010126013 | I53: =H5/inputoutput!I15 -> 0.074961772 | J53: =I5/inputoutput!J15 -> 0.018592667 | ... U53: =T5/inputoutput!U15 -> 0.0033929564
A54: 5 | B54: D | C54: =B6/inputoutput!C16 -> 0.00066707414 | D54: =C6/inputoutput!D16 -> 0.020330257 | E54: =D6/inputoutput!E16 -> 0.012861982 | F54: =E6/inputoutput!F16 -> 1.4660097 | G54: =F6/inputoutput!G16 -> 0.11128496 | H54: =G6/inputoutput!H16 -> 0.0097607147 | I54: =H6/inputoutput!I16 -> 0.0075562846 | J54: =I6/inputoutput!J16 -> 0.034334309 | ... U54: =T6/inputoutput!U16 -> 0.0015253939
A55: 6 | B55: E | C55: =B7/inputoutput!C17 -> 0.0014222267 | D55: =C7/inputoutput!D17 -> 0.00062246303 | E55: =D7/inputoutput!E17 -> 0.23500122 | F55: =E7/inputoutput!F17 -> 0.0064148005 | G55: =F7/inputoutput!G17 -> 0.018489103 | H55: =G7/inputoutput!H17 -> 0.032376492 | I55: =H7/inputoutput!I17 -> 0.011498005 | J55: =I7/inputoutput!J17 -> 0.016006172 | ... U55: =T7/inputoutput!U17 -> 0.014035246
...

Sheet hhincome

Sheet finance
B2: per adult national wealth | C2: 201355.69
B4: % of national welath by skill
C5: low | D5: middle | E5: high
C6: 0.03366 | D6: 0.21489 | E6: 0.51665
C8: capitalists
C9: 0.2348
B11: Initial interest rate | C11: 0.029375

Sheet labour
B2: ind -> | C2: A | D2: B | E2: C | F2: 19 | G2: D | H2: E | I2: F | J2: G | K2: H | L2: I | M2: J | N2: K | O2: L | P2: M-N | Q2: O | R2: P | S2: Q | T2: R | U2: S_T_U
B3: initial employment | C3: 959500 | D3: 25800 | E3: 4000000 | F3: 21600 | G3: 185853 | H3: 92347 | I3: 2000000 | J3: 4000000 | K3: 1000000 | L3: 1000000 | M3: 597300 | N3: 690300 | O3: 177400 | P3: 3000000 | Q3: 1000000 | R3: 2000000 | S3: 2000000 | T3: 318100 | U3: 2000000
B4: hours/year per capita | C4: 2610 | D4: 1821 | E4: 1742 | F4: 1833 | G4: 1794 | H4: 1794 | I4: 1908 | J4: 1945 | K4: 1951 | L4: 1964 | M4: 1848 | N4: 1791 | O4: 2185 | P4: 1770 | Q4: 1555 | R4: 1137 | S4: 1565 | T4: 1700.9 | U4: 1597.8
B5: labour productivity | C5: 20.557 | D5: 180.656 | E5: 116.455 | F5: 1389.5614 | G5: 245.745 | H5: 245.745 | I5: 69.569 | J5: 44.648 | K5: 79.617 | L5: 38.563 | M5: 116.957 | N5: 107.277 | O5: 563.546 | P5: 53.961 | Q5: 64.425 | R5: 42.407 | S5: 52.886 | T5: 76.347 | U5: 16.234
B7: hours/week | C7: 40
B8: weeks/year | C8: 44.432
A10: initial employment shares
B11: skill
B12: low | C12: 0.67229459 | D12: 0.45748209 | E12: 0.44252943 | F12: 0.44252943 | G12: 0.17196505 | H12: 0.52789107 | I12: 0.5908133 | J12: 0.41236043 | K12: 0.41496061 | L12: 0.47728572 | M12: 0.053410956 | N12: 0.063110223 | O12: 0.17706677 | P12: 0.25403962 | Q12: 0.19644741 | R12: 0.084653158 | S12: 0.15839937 | T12: 0.22314687 | U12: 0.46358182
B13: middle | C13: 0.29606377 | D13: 0.37671917 | E13: 0.47986329 | F13: 0.47986329 | G13: 0.65932878 | H13: 0.4122809 | I13: 0.37314587 | J13: 0.51588561 | K13: 0.52317881 | L13: 0.47849425 | M13: 0.62585288 | N13: 0.63066909 | O13: 0.67574231 | P13: 0.45582267 | Q13: 0.5876084 | R13: 0.40789574 | S13: 0.40290405 | T13: 0.5077399 | U13: 0.4386822
B14: high | C14: 0.03164164 | D14: 0.16579874 | E14: 0.07760728 | F14: 0.07760728 | G14: 0.16870617 | H14: 0.059828038 | I14: 0.036040837 | J14: 0.071753967 | K14: 0.06186058 | L14: 0.044220027 | M14: 0.32073616 | N14: 0.30622069 | O14: 0.14719092 | P14: 0.29013771 | Q14: 0.21594419 | R14: 0.5074511 | S14: 0.43869658 | T14: 0.26911323 | U14: 0.097735979
A16: initial male share
B17: low | C17: 0.71587811 | D17: 0.96071924 | E17: 0.7438205 | F17: 0.7438205 | G17: 0.91166165 | H17: 0.94745516 | I17: 0.98442152 | J17: 0.67702876 | K17: 0.92331731 | L17: 0.50040947 | M17: 0.66318696 | N17: 0.64773295 | O17: 0.53432148 | P17: 0.46806781 | Q17: 0.81461492 | R17: 0.34860699 | S17: 0.26093166 | T17: 0.65974578 | U17: 0.25463158
B18: middle | C18: 0.69311411 | D18: 0.84263838 | E18: 0.72753053 | F18: 0.72753053 | G18: 0.79880215 | H18: 0.77162559 | I18: 0.89233866 | J18: 0.5450397 | K18: 0.73886863 | L18: 0.49842439 | M18: 0.67468281 | N18: 0.55719044 | O18: 0.56141183 | P18: 0.45706926 | Q18: 0.64304502 | R18: 0.17636856 | S18: 0.23138113 | T18: 0.58527994 | U18: 0.25834436
B19: high | C19: 0.62583862 | D19: 0.56579333 | E19: 0.68013636 | F19: 0.68013636 | G19: 0.69353445 | H19: 0.65367279 | I19: 0.7864799 | J19: 0.468567 | K19: 0.58356228 | L19: 0.3582242 | M19: 0.63826276 | N19: 0.5776231 | O19: 0.51353153 | P19: 0.56651974 | Q19: 0.54824092 | R19: 0.27097559 | S19: 0.40629957 | T19: 0.50019278 | U19: 0.30910702
A21: trend skill distribution
B22: skill | C22: A | D22: B | E22: C | F22: 19 | G22: D | H22: E | I22: F | J22: G | K22: H | L22: I | M22: J | N22: K | O22: L | P22: M-N | Q22: O | R22: P | S22: Q | T22: R | U22: S_T_U
A23: low | B23: 3 | C23: -0.010984866 | D23: 0.004503256 | E23: -0.00910523 | F23: -0.00910523 | G23: -0.001907989 | H23: 0.000882887 | I23: -0.007839147 | J23: -0.010090043 | K23: -0.00786517 | L23: -0.009419759 | M23: -0.002927156 | N23: -0.003634047 | O23: -0.00655519 | P23: -0.004242882 | Q23: -0.009383563 | R23: -0.000941819 | S23: -0.000321875 | T23: -0.00604345 | U23: -0.003844612
A24: middle | B24: 2 | C24: 0.00801136 | D24: -0.010245814 | E24: 0.004077426 | F24: 0.004077426 | G24: -0.002841951 | H24: -0.004869116 | I24: 0.008305821 | J24: 0.004595912 | K24: 0.002596483 | L24: 0.004069943 | M24: -0.012423926 | N24: -0.007277526 | O24: -0.000883894 | P24: -0.005263575 | Q24: 0.000212364 | R24: -0.006603676 | S24: -0.010003993 | T24: -0.00776222 | U24: 0.000938113
A25: high | B25: 1 | C25: 0.002973505 | D25: 0.005742558 | E25: 0.005027804 | F25: 0.005027804 | G25: 0.00474994 | H25: 0.003986229 | I25: -0.000466674 | J25: 0.005494131 | K25: 0.005268687 | L25: 0.005349815 | M25: 0.015351082 | N25: 0.010911572 | O25: 0.007439084 | P25: 0.009506457 | Q25: 0.009171199 | R25: 0.007545496 | S25: 0.010325868 | T25: 0.01380567 | U25: 0.002906499
C26: =SUM(C23:C25) -> -1e-09 | D26: =SUM(D23:D25) -> 0 | E26: =SUM(E23:E25) -> 0 | F26: =SUM(F23:F25) -> 0 | G26: =SUM(G23:G25) -> 0 | H26: =SUM(H23:H25) -> 0 | I26: =SUM(I23:I25) -> 0 | J26: =SUM(J23:J25) -> 0 | ... U26: =SUM(U23:U25) -> 0
A27: male share trend
A28: male share trend | C28: A | D28: B | E28: C | F28: 19 | G28: D | H28: E | I28: F | J28: G | K28: H | L28: I | M28: J | N28: K | O28: L | P28: M-N | Q28: O | R28: P | S28: Q | T28: R | U28: S_T_U
A29: low | B29: 3 | C29: 0.005156183 | D29: -0.00363147 | E29: 0.002374804 | F29: 0.002374804 | G29: 0.004401581 | H29: 0.000216317 | I29: -0.000830493 | J29: 0.000443641 | K29: -5.81545e-05 | L29: -0.001002484 | M29: 0.005054312 | N29: -0.010421292 | O29: 0.014764016 | P29: -0.011202445 | Q29: 0.004915156 | R29: 0.00460166 | S29: -0.006362619 | T29: 0.003496229 | U29: -0.001569554
A30: middle | B30: 2 | C30: 0.004284152 | D30: -0.000745691 | E30: 0.002446215 | F30: 0.002446215 | G30: -0.006876372 | H30: 0.001717852 | I30: 0.0014137 | J30: 0.001087859 | K30: 8.24945e-05 | L30: -4.90814e-05 | M30: 0.006891857 | N30: -0.000420487 | O30: -0.004656666 | P30: 0.00485364 | Q30: 0.005217491 | R30: 0.003028489 | S30: 0.003020618 | T30: -0.007281943 | U30: -0.001962462
A31: high | B31: 1 | C31: 0.01201358 | D31: 0.047880662 | E31: -0.006941808 | F31: -0.006941808 | G31: 0.002297362 | H31: 0.011206884 | I31: -0.00865051 | J31: -0.00406165 | K31: -0.011632936 | L31: 0.010324301 | M31: 0.00805517 | N31: -0.010212918 | O31: 0.023668659 | P31: 0.003029038 | Q31: 0.003920358 | R31: 0.001421335 | S31: -0.008338172 | T31: -0.01636312 | U31: 0.004090896
A33: initial hourly wages
B34: gender | C34: male | D34: male | E34: male | F34: female | G34: female | H34: female
B35: skill | C35: low | D35: middle | E35: high | F35: low | G35: middle | H35: high
B36: A | C36: 7.906459 | D36: 11.2536 | E36: 19.14021 | F36: 6.0321 | G36: 9.920287 | H36: 16.34818
B37: B | C37: 15.28288 | D37: 20.92024 | E37: 38.48701 | F37: 8.942625 | G37: 17.35615 | H37: 30.72777
B38: C | C38: 14.13492 | D38: 17.39997 | E38: 34.90657 | F38: 17.72815 | G38: 16.26851 | H38: 22.04941
B39: 19 | C39: 22.63519 | D39: 27.86374 | E39: 55.89823 | F39: 28.38928 | G39: 26.05186 | H39: 35.30919
B40: D | C40: 20.13958 | D40: 19.81088 | E40: 31.43448 | F40: 20.33497 | G40: 19.24325 | H40: 49.3732
B41: E | C41: 20.8292 | D41: 20.73619 | E41: 31.06092 | F41: 21.43938 | G41: 19.31749 | H41: 87.7809
B42: F | C42: 13.16168 | D42: 15.6836 | E42: 20.09932 | F42: 15.4146 | G42: 15.50682 | H42: 16.98804
B43: G | C43: 13.22353 | D43: 14.94682 | E43: 20.14878 | F43: 14.34761 | G43: 15.41981 | H43: 16.67556
B44: H | C44: 14.92078 | D44: 17.44551 | E44: 19.50073 | F44: 23.59775 | G44: 17.19493 | H44: 18.65643
B45: I | C45: 10.50308 | D45: 13.03859 | E45: 11.54004 | F45: 11.58356 | G45: 14.5522 | H45: 11.34235
B46: J | C46: 15.91191 | D46: 22.07081 | E46: 26.69506 | F46: 16.07927 | G46: 20.70457 | H46: 21.67731
...

Sheet government
B2: employees social contribution | C2: 0.0919
B3: employers social contribution | C3: 0.2381
B5: BENEFITS
B6: SD per capita | C6: 654.16997
B7: FC per child | C7: 1278.1188
B8: ub coverage ratio | C8: 0.46236882
B9: ub wage ratio | C9: 0.53040729
B10: pw ratio | C10: 0.78554628
B11: initial other benefits per capita | C11: 118.53433
B13: FINAL CONSUMPTION | C13: A | D13: B | E13: C | F13: C19 | G13: D | H13: E | I13: F | J13: G | K13: H | L13: I | M13: J | N13: K | O13: L | P13: M-N | Q13: O | R13: P | S13: Q | T13: R | U13: S-U
B14: total final cons expenditure | C14: 486370000 | D14: 5460000 | E14: 6215820000 | F14: 11720000 | G14: 107490000 | H14: 354260000 | I14: 1338860000 | J14: 4438460000 | K14: 5954160000 | L14: 814590000 | M14: 706860000 | N14: 38210000 | O14: 1384090000 | P14: 3271230000 | Q14: 130983780000 | R14: 57901820000 | S14: 106124550000 | T14: 5401590000 | U14: 1450970000
B15: trend in total final cons exp | C15: 21831207 | D15: 3377931 | E15: 1.1173086e+08 | F15: -1222069 | G15: 3549655.2 | H15: 2.2559017e+08 | I15: -1.6305155e+08 | J15: -11884310 | K15: 99095000 | L15: -98063276 | M15: 3.6193431e+08 | N15: 22979310 | O15: -1.329781e+08 | P15: 5.8098207e+08 | Q15: -1.7872245e+09 | R15: -59911379 | S15: 4.7700672e+08 | T15: -1.519019e+08 | U15: -47276552
B18: OTHER EXPENDITURE
B19: wage ratio | C19: 0.62805973
B20: investment ratio | C20: 0.1638157
B22: inflation target | C22: 0.02
B23: initial i | C23: 0.01
B24: Government consolidated gross debt | C24: 1920620000000
B26: VAT rate
A27: Year | C27: A | D27: B | E27: C | F27: C19 | G27: D | H27: E | I27: F | J27: G | K27: H | L27: I | M27: J | N27: K | O27: L | P27: M-N | Q27: O | R27: P | S27: Q | T27: R | U27: S-U
A28: 2010 | B28: vat effective rates 2010 | C28: 0.062385851 | D28: 0.05374777 | E28: 0.031952753 | F28: 0.10384029 | G28: 0.051120193 | H28: 0.057449673 | I28: 0.033483484 | J28: 0.030125064 | K28: 0.031999384 | L28: 0.025307903 | M28: 0.028748601 | N28: 0.051770586 | O28: 0.013760836 | P28: 0.022717243 | Q28: 0.041214814 | R28: 0.055215629 | S28: 0.043100834 | T28: 0.026087794 | U28: 0.010866905
B41: Personal income tax (Irpef) rates
B42: Tax bracket | C42: Bracket treshold | D42: tax rate
B43: 0-15000 | C43: 0 | D43: 0.23
B44: 15000-28000 | C44: 15000 | D44: 0.27
B45: 28000-55000 | C45: 28000 | D45: 0.38
B46: 55000-75000 | C46: 55000 | D46: 0.41
B47: >75000 | C47: 75000 | D47: 0.43
B49: Corporate income tax rate (Ires)
A50: Year | B50: Year Vensim | C50: tax rate
A51: 2010 | B51: =A51-2010 -> 0 | C51: 0.275
A52: 2011 | B52: =A52-2010 -> 1 | C52: 0.275
A53: 2012 | B53: =A53-2010 -> 2 | C53: 0.275
A54: 2013 | B54: =A54-2010 -> 3 | C54: 0.275
A55: 2014 | B55: =A55-2010 -> 4 | C55: 0.275
A56: 2015 | B56: =A56-2010 -> 5 | C56: 0.275
A57: 2016 | B57: =A57-2010 -> 6 | C57: 0.275
A58: 2017 | B58: =A58-2010 -> 7 | C58: 0.24
A59: 2018 | B59: =A59-2010 -> 8 | C59: 0.24
A60: 2019 | B60: =A60-2010 -> 9 | C60: 0.24
...

Sheet technology
A1: A DOM | B1: A | C1: B | D1: C | E1: C19 | F1: D | G1: E | H1: F | I1: G | J1: H | K1: I | L1: J | M1: K | N1: L | O1: M+N | P1: O | Q1: P | R1: Q | S1: R | T1: S+T+U
A2: A | B2: 0.10374531 | C2: 0.00021960427 | D2: 0.023262971 | E2: 9.9231483e-05 | F2: 0.00095125781 | G2: 0.001087909 | H2: 0.0003440885 | I2: 0.0081522982 | J2: 0.0018612219 | K2: 0.013668846 | L2: 0.0004571417 | M2: 0.00011524293 | N2: 0.00011186341 | O2: 0.0014537208 | P2: 0.00047406872 | Q2: 0.00027292318 | R2: 0.0006611551 | S2: 0.0015873156 | T2: 0.00062449107
A3: B | B3: 0.00024067632 | C3: 0.0038106129 | D3: 0.0022726222 | E3: 0.013841445 | F3: 0.010831296 | G3: 0.0035425532 | H3: 0.003017632 | I3: 0.0014221974 | J3: 0.00033081334 | K3: 0.00046257946 | L3: 0.00043516705 | M3: 0.0001544351 | N3: 0.00020996925 | O3: 0.00058046793 | P3: 0.00014802429 | Q3: 0.00018682655 | R3: 0.00037112812 | S3: 0.00040903603 | T3: 0.00030312144
A4: C | B4: 0.15540443 | C4: 0.111651 | D4: 0.24250922 | E4: 0.053374266 | F4: 0.019935821 | G4: 0.093877059 | H4: 0.15233043 | I4: 0.064435477 | J4: 0.065102959 | K4: 0.18111868 | L4: 0.069920821 | M4: 0.019499101 | N4: 0.014628377 | O4: 0.074389129 | P4: 0.01076963 | Q4: 0.0106747 | R4: 0.052080761 | S4: 0.057757285 | T4: 0.044605152
A5: C19 | B5: 0.029498354 | C5: 0.022015147 | D5: 0.0091784903 | E5: 0.084505953 | F5: 0.031090322 | G5: 0.025653472 | H5: 0.0081445508 | I5: 0.0039813313 | J5: 0.033032826 | K5: 0.000656282 | L5: 0.00031203799 | M5: 0.00034936394 | N5: 3.7482865e-05 | O5: 0.0019488431 | P5: 0.0025597985 | Q5: 8.1513477e-05 | R5: 0.00075044272 | S5: 0.00058746695 | T5: 0.0012577086
A6: D | B6: 0.018888919 | C6: 0.024307134 | D6: 0.020732432 | E6: 0.020016684 | F6: 0.30357991 | G6: 0.028412783 | H6: 0.0037415302 | I6: 0.011252114 | J6: 0.011751931 | K6: 0.019227682 | L6: 0.0043288117 | M6: 0.0042799646 | N6: 0.0007577845 | O6: 0.0064691959 | P6: 0.015254722 | Q6: 0.0061493929 | R6: 0.0087796192 | S6: 0.0065640574 | T6: 0.023766053
A7: E | B7: 0.0081690883 | C7: 0.030056323 | D7: 0.011936162 | E7: 0.003973069 | F7: 0.021140546 | G7: 0.21525043 | H7: 0.0040594149 | I7: 0.0025856282 | J7: 0.0043482682 | K7: 0.0035673885 | L7: 0.0031940125 | M7: 0.0016085093 | N7: 0.00067017218 | O7: 0.0025592154 | P7: 0.0031983923 | Q7: 0.00151532 | R7: 0.0043324979 | S7: 0.0048031256 | T7: 0.019253908
A8: F | B8: 0.011602638 | C8: 0.0067577326 | D8: 0.0068848162 | E8: 0.0067258729 | F8: 0.0065831297 | G8: 0.011315728 | H8: 0.29089368 | I8: 0.007759392 | J8: 0.011487562 | K8: 0.007792745 | L8: 0.011685182 | M8: 0.0050567297 | N8: 0.013081903 | O8: 0.011680775 | P8: 0.017752504 | Q8: 0.0061912215 | R8: 0.013450452 | S8: 0.006196774 | T8: 0.0077591124
A9: G | B9: 0.031991254 | C9: 0.031666516 | D9: 0.059494901 | E9: 0.062096102 | F9: 0.037184913 | G9: 0.045317342 | H9: 0.024035044 | I9: 0.049379108 | J9: 0.037911963 | K9: 0.033863726 | L9: 0.033672915 | M9: 0.013016671 | N9: 0.0034296572 | O9: 0.038919323 | P9: 0.0047875229 | Q9: 0.00366712 | R9: 0.020388172 | S9: 0.020919716 | T9: 0.011691323
A10: H | B10: 0.018871879 | C10: 0.044837453 | D10: 0.034195869 | E10: 0.035695819 | F10: 0.049166011 | G10: 0.024893576 | H10: 0.019649978 | I10: 0.061927751 | J10: 0.19267361 | K10: 0.014324642 | L10: 0.028430044 | M10: 0.012891432 | N10: 0.0019069758 | O10: 0.023839111 | P10: 0.014502194 | Q10: 0.0063549372 | R10: 0.0068465456 | S10: 0.016314867 | T10: 0.01137649
A11: I | B11: 0.00083014023 | C11: 0.0038074663 | D11: 0.0042677367 | E11: 0.001466283 | F11: 0.0073763835 | G11: 0.00079360149 | H11: 0.01059873 | I11: 0.0082799992 | J11: 0.004686962 | K11: 0.0062902013 | L11: 0.0085778347 | M11: 0.0020028171 | N11: 0.0015473195 | O11: 0.011585764 | P11: 0.0030720465 | Q11: 0.002733777 | R11: 0.011239618 | S11: 0.010315096 | T11: 0.0049842611
